Workbook
Name aa: #REF!
Name aa: #REF!
Name aa: #REF!
Name aa: #REF!
Name aa: #REF!
Name aa: #REF!
Name aa: #REF!
Name aa: #REF!
Name bh: [1]Preliminaries!$J$1
Name bh: [1]Preliminaries!$J$1
Name bh: #REF!
Name Civil4: #REF!
Name Civil4: #REF!
Name Civil4: #REF!
Name Civil4: #REF!
Name Civil4: #REF!
Name Civil4: #REF!
Name Civil4: #REF!
Name Civil4: #REF!
Name d: #REF!
Name d: #REF!
Name d: #REF!
Name d: #REF!
Name d: #REF!
Name d: #REF!
Name d: #REF!
Name date: #REF!
Name date: #REF!
Name date: #REF!
Name date: #REF!
Name date: #REF!
Name date: #REF!
Name date: #REF!
Name date: #REF!
Name daz: #REF!
Name daz: #REF!
Name daz: #REF!
Name daz: #REF!
Name ddd: #REF!
Name ddd: #REF!
Name ddd: #REF!
Name ddd: #REF!
Name for: #REF!
Name for: #REF!
Name for: #REF!
Name for: #REF!
Name for: #REF!
Name job: #REF!
Name job: #REF!
Name job: #REF!
Name job: #REF!
Name job: #REF!
Name No: #REF!
Name No: #REF!
Name No: #REF!
Name No: #REF!
Name No: #REF!
Name qqq: #REF!
Name qqq: #REF!
Name qqq: #REF!

Sheet V1
B6: SUMMARY
V7: Cost | W7: 0 | Y7: Cost | Z7: 0
B8: JOB DESCRIPTION: | K8: 46156 | V8: Markup | W8: 0.1 | Y8: Markup | Z8: 0.1
B9: SITE ADDRESS: | K9: TCS Quote #: 2378 | V9: Charge = | W9: =W7+(W7*W8) -> 0 | Y9: Charge = | Z9: =Z7+(Z7*Z8) -> 0
R10: Cost | S10: (Cost + O/H) + Profit
K11: TOTALS
B13: PART A | F13: Stormwater Drainage (Civil & Hydraulic) | K13: =S13 -> 17860.398 | R13: ='SW Zone Sumry'!F70 -> 13644.307 | S13: =((R13/$R$17)*($R$27-$R$17))+R13 -> 17860.398
R17: =SUM(R13:R15) -> 13644.307 | S17: =SUM(S13:S15) -> 17860.398
T19: Manual Calc
J20: TOTAL ex GST | K20: =SUM(K13:K17) -> 17860.398 | P20: Prelim | Q20: 0.035 | R20: =R17*Q20 -> 477.55075 | S20: of total cost | T20: ='Prelim_OH-Check'!F42 -> 0
P21: O/H | Q21: 0.155 | R21: =R17*Q21 -> 2114.8676 | S21: of total cost | T21: ='Prelim_OH-Check'!F47 -> 0
P23: Sub Total | R23: =SUM(R17:R22) -> 16236.725 | S23: total cost + Prelim + O/H
P26: Gross Profit | Q26: 0.1 | R26: =R23*Q26 -> 1623.6725 | S26: Exl equip & Fixt
P27: Grand Total | R27: =SUM(R23:R26) -> 17860.398
P29: Total Markup | Q29: =SUM(Q20:Q28) -> 0.29
P31: Net Profit Incl Equip | R31: =R26 -> 1623.6725

Sheet Prelim_OH-Check
B1: Project:
B2: Tricore -
B3: Stage 1 Version 1
A4: Item
A7: A | B7: PRELIMINARIES
C8: Unit | D8: REQ | E8: Cost ex GST | F8: Total ex GST
B9: Labour
F10: 0
B11: Contingencies; Wet Weather ?
B13: TRADESMAN_LEADING HAND | C13: Day | D13: 0 | E13: ='Staff Rates'!E17 -> 822.5 | F13: =D13*E13 -> 0
B14: TRADESMAN_PLUMBER_OPERATOR | C14: Day | D14: 0 | E14: 400 | F14: =D14*E14 -> 0
B15: T/A & Apprentice | C15: Day | D15: 0 | E15: 597.62762 | F15: =D15*E15 -> 0
B16: Crew #1 | C16: Day | D16: 0 | E16: 1895.3002 | F16: =D16*E16 -> 0
B17: Crew #2 | C17: Day | D17: 0 | E17: 1511.9133 | F17: 0
B19: Equipment, Hire, Subbies
B21: Dual CabUte | C21: item | D21: 0 | E21: 0 | F21: =D21*E21 -> 0
B22: 10m3_Skip Bin | C22: item | D22: 0 | E22: 0 | F22: =D22*E22 -> 0
B23: TCS Container; Ecl Freight | C23: item | D23: 0 | E23: 0 | F23: =D23*E23 -> 0
B24: Fencing | C24: item | D24: 0 | E24: 0 | F24: =D24*E24 -> 0
C25: item | D25: 0 | E25: 0 | F25: =D25*E25 -> 0
B27: Misc.
B29: Site Admin, Stationary etc - GREENSTAR ADMINS | C29: item | D29: 0 | E29: 1600 | F29: =D29*E29 -> 0
B30: Site PPE | C30: item | D30: 0 | E30: 400 | F30: =D30*E30 -> 0
B31: Site Consumables- Paint, Tapes etc | C31: item | D31: 0 | E31: 180 | F31: =D31*E31 -> 0
B32: Site Management - Bollards, Pickets, Barrier Mesh etc | C32: item | D32: 0 | E32: 400 | F32: =D32*E32 -> 0
B33: Staff Refreshments - ONSITE | C33: item | D33: 0 | E33: 50 | F33: =D33*E33 -> 0
B34: Staff Refreshments - Offsite | C34: item | D34: 0 | E34: 50 | F34: =D34*E34 -> 0
B35: TOOLS - Roll Grover - S&M | C35: item | D35: 0 | E35: 320 | F35: =D35*E35 -> 0
B36: TOOLS - Poly Welder - S&M | C36: item | D36: 0 | E36: 320 | F36: =D36*E36 -> 0
B37: TOOLS - Wacker/Laser/Misc - S&M | C37: item | D37: 0 | E37: 580 | F37: =D37*E37 -> 0
B38: TOOLS - Demo Saw Trolley - PURCHASE | C38: item | D38: 0 | E38: 0 | F38: =D38*E38 -> 0
B39: TOOLS - Consumabls - Blades, etc | C39: item | D39: 0 | E39: 420 | F39: =D39*E39 -> 0
E42: Total TCS Prelims | F42: =SUM(F11:F41) -> 0
A45: A | B45: OverHeads
C46: Unit | D46: REQ | E46: Cost ex GST | F46: Total ex GST
B47: TriCore Overheads - COMPLETE…PER MONTH | C47: item | D47: 0 | E47: 20000 | F47: =D47*E47 -> 0
C48: item | D48: 0 | E48: 0 | F48: 0
C49: item | D49: 0 | E49: 0 | F49: 0
E53: Total TCS O/H | F53: =SUM(F47:F52) -> 0

Sheet SW Zone Sumry
B1: Project:
B2: Tricore -
B3: Stage 1 Version 1
A4: Item
A8: B | B8: Labour
H9: TOTAL Labour
B10: From Proposed Program
H11: =SUM(F13:F19) -> 0
B12: DAY
B13: TRADESMAN_LEADING HAND | C13: Day | E13: ='Staff Rates'!E17 -> 822.5 | F13: =E13*D13 -> 0
B14: CREW - Fire & WAT | C14: Day | E14: ='Staff Rates'!E24 -> 2222.5 | F14: =E14*D14 -> 0
B15: CREW - Drainage | C15: Day | E15: ='Staff Rates'!E24 -> 2222.5 | F15: =E15*D15 -> 0
B16: CREW #3 | C16: Day | E16: ='Staff Rates'!E31 -> 2222.5 | F16: =E16*D16 -> 0
B17: T/A & Apprentice | C17: Day | E17: ='Staff Rates'!E52 -> 612.5 | F17: =E17*D17 -> 0
B18: TRADESMAN.1 | C18: Day | E18: ='Staff Rates'!E45 -> 805 | F18: =E18*D18 -> 0
B19: TRADESMAN.2 | C19: Day | E19: ='Staff Rates'!E45 -> 805 | F19: =E19*D19 -> 0
B21: HOUR
B22: TRADESMAN_LEADING HAND | C22: HR | E22: 0 | F22: =E22*D22 -> 0
B23: TRADESMAN_PLUMBER_OPERATOR | C23: HR | E23: 0 | F23: =E23*D23 -> 0
B24: T/A & Apprentice | C24: HR | E24: 0 | F24: =E24*D24 -> 0
B25: Crew #1 | C25: HR | E25: 0 | F25: =E25*D25 -> 0
B26: Crew #2 | C26: HR | E26: 0 | F26: =E26*D26 -> 0
A28: C | B28: Equipment, Hire, Subbies | H28: TOTAL Equip
B30: Skid Steer Loader_Wheeled | C30: ea | E30: 300 | F30: =E30*D30 -> 0 | H30: =SUM(F30:F39) -> 0
B31: Skid Steer Loader_Wheeled | C31: ea | E31: 300 | F31: =E31*D31 -> 0
B32: 8Ton_Excavator | C32: ea | E32: 300 | F32: =E32*D32 -> 0
B33: 20-24Ton_Excavator | C33: ea | E33: 450 | F33: =E33*D33 -> 0
B34: 14-16Ton_Excavator | C34: ea | E34: 440 | F34: =E34*D34 -> 0
B35: 6-12T_Tipper Truck | C35: ea | E35: 400 | F35: =E35*D35 -> 0
B36: <10T_Articulated Site Tipper | C36: ea | E36: 341 | F36: =E36*D36 -> 0
B37: Trench Roller_Dbl Drum_Remote | C37: ea | E37: 180 | F37: =E37*D37 -> 0
B38: Trench Roller_Dbl Drum_Remote | C38: ea | E38: 180 | F38: =E38*D38 -> 0
B39: <26Ft_Scissor Lift - Diesel | C39: ea | E39: 150 | F39: =E39*D39 -> 0
B40: Compaction Testing | C40: ea | E40: 122 | F40: =E40*D40 -> 0
B41: CCTV | C41: ea | E41: 1680 | F41: =E41*D41 -> 0
B42: Misc Hire/Tooling | C42: ea | E42: 1680 | F42: =E42*D42 -> 0
... B50: Fuel - Diesel_Machinery & Equip/WEEK (Average) | C50: ea | E50: 2500 | F50: =E50*D50 -> 0
E51: **Mini tankers Avg 6,000/Mnth
A53: D | B53: Material
B55: Material; | C55: ea | D55: 1 | E55: =SW_Mataterial!F227 -> 13273.02 | F55: =E55*D55 -> 13273.02
...

Sheet SW_Mataterial
B2: SECTION A
B3: STORMWATER DRAINAGE
B4: Description | C4: Qty | D4: Unit | E4: Rate | F4: Total
B6: rcp/frc
B7: PIPE 675MM - RCP_C3 | D7: m | E7: 270 | F7: =C7*E7 -> 0
B8: PIPE 600MM - RCP_C4 | D8: m | E8: =13169/60 -> 219.48333 | F8: =C8*E8 -> 0
B9: PIPE 600MM - RCP_C2 | D9: m | E9: 203 | F9: =C9*E9 -> 0
B10: PIPE 525MM - RCP_C4 | D10: m | E10: 187 | F10: =C10*E10 -> 0
B11: PIPE 525MM - RCP_C3 | D11: m | E11: 140.91 | F11: =C11*E11 -> 0
B12: PIPE 450MM - RCP_C4 | D12: m | E12: =7072.78/53 -> 133.44868 | F12: =C12*E12 -> 0
B13: PIPE 375MM - RCP_C4 | D13: m | E13: =21819.2/243 -> 89.790947 | F13: =C13*E13 -> 0
B14: PIPE 375MM - RCP_C3 | D14: m | E14: 87.11 | F14: =C14*E14 -> 0
B15: PIPE 375MM - RCP_C2 | D15: m | E15: 87.11 | F15: =C15*E15 -> 0
B16: SW_SN8 RIBBED (Blackmax or similar) | D16: m
B17: PIPE Ribbed RRJ 900MM | D17: m
B18: PIPE Ribbed RRJ 825MM | D18: m
B19: PIPE Ribbed RRJ 750MM | D19: m | E19: 232 | F19: =C19*E19 -> 0
B20: PIPE Ribbed RRJ 675MM | D20: m | E20: 232 | F20: =C20*E20 -> 0
B21: PIPE Ribbed RRJ 600MM | D21: m | E21: 120.08 | F21: =C21*E21 -> 0
B22: PIPE Ribbed RRJ 525MM | D22: m | E22: 89 | F22: =C22*E22 -> 0
B23: PIPE Ribbed RRJ 450MM | D23: m | E23: 62.05 | F23: =C23*E23 -> 0
B24: PIPE Ribbed RRJ 375MM | D24: m | E24: 51.55 | F24: =C24*E24 -> 0
B25: PIPE Ribbed RRJ 300MM | C25: 25 | D25: m | E25: 41 | F25: =C25*E25 -> 1025
B26: PIPE Ribbed RRJ 225MM | D26: m | E26: 26 | F26: =C26*E26 -> 0
B27: PIPE Ribbed RRJ 150MM | D27: m | E27: 9.72 | F27: =C27*E27 -> 0
B29: SW_SN8 PVC Pipeline
B30: PIPE DWV SN8 PVC S/WELD 375MM | D30: m | E30: 96.33 | F30: =C30*E30 -> 0
B31: PIPE DWV SN8 PVC S/WELD 300MM | D31: m | E31: 54.33 | F31: =C31*E31 -> 0
B32: PIPE DWV SN4 PVC S/WELD 300MM | D32: m | E32: 49.833333 | F32: =C32*E32 -> 0
B33: PIPE SW H/D PVC S/WELD 300MM | D33: m | E33: 40 | F33: =C33*E33 -> 0
B34: PIPE DWV SN8 PVC S/WELD 225MM | D34: m | E34: =9427.2/237 -> 39.777215 | F34: =C34*E34 -> 0
B35: PIPE DWV SN4 PVC S/WELD 225MM | D35: m | E35: 31 | F35: =C35*E35 -> 0
B36: 50mm PVC Class 12 | D36: m | E36: 18 | F36: =C36*E36 -> 0
B37: PIPE DWV SN8 PVC S/WELD 150MM | D37: m | E37: 14.166667 | F37: =C37*E37 -> 0
B38: PIPE DWV SN4 PVC S/WELD 150MM | D38: m | E38: 11.666667 | F38: =C38*E38 -> 0
B39: PIPE DWV SN4 PVC S/WELD 100MM | C39: 6 | D39: m | E39: 12 | F39: =C39*E39 -> 72
B40: SW Grade Option
B41: 300MM * 45D PVC SW JUNCTION | D41: ea | E41: 159 | F41: =C41*E41 -> 0
B42: 300X225X45D PVC SW JUNCTION | D42: ea | E42: 141.5 | F42: =C42*E42 -> 0
B43: 300MM X 225MM SW Reducer | C43: 2 | D43: ea | E43: 45 | F43: =C43*E43 -> 90
...

Sheet SW_Pit Takeoff
C1: 44918
G2: Total Qty
C3: 600 Grte/frm Height | E3: 0.055
C4: 600*900 Grte/frm Height | E4: 0.08
C5: 1.2*1.2 Grte/frm Height | E5: 0.14
C6: 1200*9*6 ASPRO Height | E6: 0.175
C7: 600 infl Height | E7: 0.055
C8: 600 V Grate Height | E8: 0.15
C9: 600 Pit Base Height | E9: 0.6
C10: 600 Pit Riser Height | E10: 0.15
C11: 600 Pit Riser Height | E11: 0.3
C12: 600 Pit Riser Height | E12: 0.6
C13: 600 Pit Riser Height | E13: 0.9
C14: 900*900 Pit Base Height | E14: 0.9
... C18: 600*900 Pit Riser Height | E18: 0.9
C19: 1050 Chmbr Base Height | E19: 1.2 | F19: 1200
C20: 1050 Chmbr Riser Height | E20: 0.15
C21: 1050 Chmbr Riser Height | E21: 0.3
C22: 1050 Chmbr Riser Height | E22: 0.6
C23: 1050 Chmbr Riser Height | E23: 0.9
C24: 1050 Chmbr Riser Height | E24: 1.2
D25: 1200*1200*200 | E25: 0.2 | AG25: 0.2for1.2
O26: Manual calc | AD26: V3 | AG26: Manual calc | AV26: V3 | AX26: Manual calc
C27: Pit Count | D27: PIT No. | E27: Grate RL | F27: Type | G27: Grate Size | H27: Chamber | I27: Outlet IL | J27: Depth | M27: Riser Height Req. w/ base | O27: 0.15 Riser | P27: 0.3 Riser | Q27: 0.6 Riser | R27: 0.9 Riser | T27: Pit riser difference | V27: Pit Count | W27: PIT No. | X27: Grate RL | Y27: Type | Z27: Grate Size | AA27: Chamber | AB27: Outlet IL | AC27: Depth | AE27: Riser Height Req. w/base | AG27: 0.15 Riser | AH27: 0.3 Riser | AI27: 0.6 Riser | AJ27: 0.9 Riser | AK27: Pit riser difference | AM27: Pit Count | AN27: PIT No. | AO27: Grate RL | AP27: Type | AQ27: Grate Size | AR27: Chamber | AS27: Outlet IL | AT27: Depth | AW27: Riser Height Req. w/ base | AX27: 0.15 Riser | AY27: 0.3 Riser | AZ27: 0.6 Riser | BA27: 0.9 Riser | BB27: Pit riser difference
C28: 1 | J28: =E28-I28 -> 0 | M28: =J28-0.45-0.05 -> -0.5 | T28: =M28-(O28*$E$10)-(P28*$E$11)-(Q28*$E$12)-(R28*$E$13) -> -0.5 | V28: 21 | AC28: 0.986 | AD28: 1 | AE28: =AC28-$E$3-0.3 -> 0.631 | AI28: 1 | AK28: =AE28-(AG28*$E$25)-(AH28*$E$11)-(AI28*$E$12)-(AJ28*$E$13) -> 0.031 | AM28: 40 | AN28: 46 | AV28: =AT28-$E$9-$E$8 -> -0.75 | AW28: =AT28-$E$5-$E$19 -> -1.34 | BB28: =AW28-(AX28*$E$25)-(AY28*$E$11)-(AZ28*$E$12)-(BA28*$E$13) -> -1.34
C29: 2 | J29: =E29-I29 -> 0 | M29: =J29-$E$9-$E$3 -> -0.655 | T29: =M29-(O29*$E$10)-(P29*$E$11)-(Q29*$E$12)-(R29*$E$13) -> -0.655 | V29: 22 | AC29: 0.949 | AD29: =Y29-AC29 -> -0.949 | AE29: =AC29-$E$3-0.3 -> 0.594 | AI29: 1 | AK29: =AE29-(AG29*$E$10)-(AH29*$E$11)-(AI29*$E$12)-(AJ29*$E$13) -> -0.006 | AM29: 42 | AN29: 47 | AV29: =AT29-$E$9-$E$8 -> -0.75 | AW29: =AT29-$E$5-$E$19 -> -1.34 | BB29: =AW29-(AX29*$E$10)-(AY29*$E$11)-(AZ29*$E$12)-(BA29*$E$13) -> -1.34
C30: 3 | J30: =E30-I30 -> 0 | M30: =J30-$E$3-$E$9 -> -0.655 | T30: =M30-(O30*$E$10)-(P30*$E$11)-(Q30*$E$12)-(R30*$E$13) -> -0.655 | V30: 23 | AC30: =X30-AB30 -> 0 | AE30: =AC30-$E$4-$E$14 -> -0.98 | AK30: =AE30-(AG30*$E$10)-(AH30*$E$11)-(AI30*$E$12)-(AJ30*$E$13) -> -0.98 | AM30: 43 | AV30: =AT30-$E$9-$E$8 -> -0.75 | AW30: =AT30-$E$4-$E$14 -> -0.98 | BB30: =AW30-(AX30*$E$10)-(AY30*$E$11)-(AZ30*$E$12)-(BA30*$E$13) -> -0.98
C31: 4 | J31: =E31-I31 -> 0 | M31: =J31-$E$6-$E$23-$E$4 -> -1.155 | T31: =M31-(O31*$E$10)-(P31*$E$11)-(Q31*$E$12)-(R31*$E$13) -> -1.155 | V31: 24 | AD31: 2.1 | AE31: =AC31-$E$4-$E$14 -> -0.98 | AK31: =AE31-(AG31*$E$10)-(AH31*$E$11)-(AI31*$E$12)-(AJ31*$E$13) -> -0.98 | AM31: 44 | AV31: =AT31-$E$9-$E$8 -> -0.75 | AW31: =AT31-$E$4-$E$14 -> -0.98 | BB31: =AW31-(AX31*$E$10)-(AY31*$E$11)-(AZ31*$E$12)-(BA31*$E$13) -> -0.98
C32: 5 | J32: =E32-I32 -> 0 | M32: =J32-$E$3-$E$9 -> -0.655 | T32: =M32-(O32*$E$10)-(P32*$E$11)-(Q32*$E$12)-(R32*$E$13) -> -0.655 | V32: 25 | AD32: 0.86 | AE32: =AC32-$E$4-$E$14 -> -0.98 | AK32: =AE32-(AG32*$E$25)-(AH32*$E$11)-(AI32*$E$12)-(AJ32*$E$13) -> -0.98 | AM32: 45 | AV32: =AT32-$E$9-$E$8 -> -0.75
C33: 6 | J33: =E33-I33 -> 0 | M33: =J33-$E$3-$E$9 -> -0.655 | T33: =M33-(O33*$E$10)-(P33*$E$11)-(Q33*$E$12)-(R33*$E$13) -> -0.655 | V33: 26 | AD33: 2.26 | AE33: =AC33-$E$4-$E$14 -> -0.98 | AK33: =AE33-(AG33*$E$25)-(AH33*$E$11)-(AI33*$E$12)-(AJ33*$E$13) -> -0.98 | AM33: 46 | AV33: =AT33-$E$9-$E$8 -> -0.75
C34: 7 | J34: =E34-I34 -> 0 | M34: =J34-$E$4-$E$14 -> -0.98 | T34: =M34-(O34*$E$10)-(P34*$E$11)-(Q34*$E$12)-(R34*$E$13) -> -0.98 | V34: 27 | AD34: 1.96 | AE34: =AC34-$E$4-$E$14 -> -0.98 | AK34: =AE34-(AG34*$E$25)-(AH34*$E$11)-(AI34*$E$12)-(AJ34*$E$13) -> -0.98 | AM34: 47 | AV34: =AT34-$E$9-$E$8 -> -0.75
C35: 8 | J35: =E35-I35 -> 0 | M35: =J35-$E$3-$E$9 -> -0.655 | T35: =M35-(O35*$E$10)-(P35*$E$11)-(Q35*$E$12)-(R35*$E$13) -> -0.655 | V35: 28 | AD35: 2.1 | AE35: =AC35-$E$4-$E$14 -> -0.98 | AK35: =AE35-(AG35*$E$25)-(AH35*$E$11)-(AI35*$E$12)-(AJ35*$E$13) -> -0.98 | AM35: 48 | AV35: =AT35-$E$9-$E$8 -> -0.75
C36: 9 | J36: =E36-I36 -> 0 | M36: =J36-$E$6-$E$23-$E$4 -> -1.155 | T36: =M36-(O36*$E$10)-(P36*$E$11)-(Q36*$E$12)-(R36*$E$13) -> -1.155 | AD36: 2.1 | AE36: =AC36-$E$4-$E$14 -> -0.98 | AK36: =AE36-(AG36*$E$25)-(AH36*$E$11)-(AI36*$E$12)-(AJ36*$E$13) -> -0.98
C37: 10 | J37: =E37-I37 -> 0 | M37: =J37-$E$3-$E$9 -> -0.655 | T37: =M37-(O37*$E$10)-(P37*$E$11)-(Q37*$E$12)-(R37*$E$13) -> -0.655 | AD37: 2.1 | AE37: =AC37-$E$4-$E$14 -> -0.98 | AK37: =AE37-(AG37*$E$25)-(AH37*$E$11)-(AI37*$E$12)-(AJ37*$E$13) -> -0.98
C38: 11 | J38: =E38-I38 -> 0 | M38: =J38-$E$3-$E$9 -> -0.655 | T38: =M38-(O38*$E$10)-(P38*$E$11)-(Q38*$E$12)-(R38*$E$13) -> -0.655 | AD38: 2.1 | AE38: =AC38-$E$4-$E$14 -> -0.98 | AK38: =AE38-(AG38*$E$25)-(AH38*$E$11)-(AI38*$E$12)-(AJ38*$E$13) -> -0.98
C39: 12 | J39: =E39-I39 -> 0 | M39: =J39-0.45-$E$3 -> -0.505 | T39: =M39-(O39*$E$10)-(P39*$E$11)-(Q39*$E$12)-(R39*$E$13) -> -0.505 | AD39: 2.1 | AE39: =AC39-$E$4-$E$14 -> -0.98 | AK39: =AE39-(AG39*$E$25)-(AH39*$E$11)-(AI39*$E$12)-(AJ39*$E$13) -> -0.98
C40: 13 | J40: 0.767 | M40: =J40-0.45-$E$3 -> 0.262 | T40: =M40-(O40*$E$10)-(P40*$E$11)-(Q40*$E$12)-(R40*$E$13) -> 0.262 | AD40: 2.1 | AE40: =AC40-$E$4-$E$14 -> -0.98 | AK40: =AE40-(AG40*$E$10)-(AH40*$E$11)-(AI40*$E$12)-(AJ40*$E$13) -> -0.98
C41: 14 | J41: 0.882 | M41: =J41-0.45-$E$3 -> 0.377 | T41: =M41-(O41*$E$10)-(P41*$E$11)-(Q41*$E$12)-(R41*$E$13) -> 0.377 | AD41: 2.1 | AE41: =AC41-$E$4-$E$14 -> -0.98 | AK41: =AE41-(AG41*$E$25)-(AH41*$E$11)-(AI41*$E$12)-(AJ41*$E$13) -> -0.98
C42: 15 | J42: 1.291 | M42: =J42-$E$3-$E$9 -> 0.636 | T42: =M42-(O42*$E$10)-(P42*$E$11)-(Q42*$E$12)-(R42*$E$13) -> 0.636 | AD42: 2.1 | AE42: =AC42-$E$4-$E$14 -> -0.98 | AK42: =AE42-(AG42*$E$10)-(AH42*$E$11)-(AI42*$E$12)-(AJ42*$E$13) -> -0.98
C43: 16 | J43: 0.969 | M43: =J43-0.45-$E$3 -> 0.464 | T43: =M43-(O43*$E$10)-(P43*$E$11)-(Q43*$E$12)-(R43*$E$13) -> 0.464 | AD43: 2.1 | AE43: =AC43-$E$4-$E$14 -> -0.98 | AK43: =AE43-(AG43*$E$10)-(AH43*$E$11)-(AI43*$E$12)-(AJ43*$E$13) -> -0.98
...

Sheet SW_insitu Takeoff
B2: PIT/MANHOLE TAKEOFF
A3: DESCRIPTION | B3: Design Depth | C3: Grate/Finish | D3: Aspro | E3: Total Chamber Height | F3: Chamber Concrete volume/m3 | G3: Base Concrete volume/m3 | H3: Total Concrete volume/m3 | J3: Dia | K3: Area of circle
H4: =F4+G4 -> 0 | J4: 2.1 | K4: =PI()*(J4/2)^2 -> 3.4636059 | L4: m2
J5: 2.6 | K5: =PI()*(J5/2)^2 -> 5.3092916 | L5: m2
K6: =PI()*(J6/2)^2 -> 0 | L6: m2
K7: =PI()*(J7/2)^2 -> 0 | L7: m2
J10: 32 | K10: MPA | L10: 290 | M10: $/m3
L24: =H24-G24 -> 0
H27: =SUM(H4:H16) -> 0 | I27: m3 | J27: =H27*L10 -> 0

Sheet Program
A1: Project Program | D1: MONTH 1 | AF1: MONTH 2 | BH1: MONTH 3 | CJ1: MONTH 4 | DL1: MONTH 5
D2: Week 1 / SEPT | K2: Week 2 / SEPT | R2: Week 3 / SEPT | Y2: Week 4 / SEPT | AF2: Week 5 / OCT | AM2: Week 6 / OCT | AT2: Week 7 / OCT | BA2: Week 8 / OCT | BH2: Week 9 / NOV | BO2: Week 10 / NOV | BV2: Week 11 / NOV | CC2: Week 12 / NOV | CJ2: Week 13 / NOV-DEC | CQ2: Week 14 / DEC | CX2: Week 15 / DEC | DE2: Week 16 / NOV | DL2: Week 17 / NOV-DEC
D3: M | E3: Tu | F3: W | G3: Th | H3: F | I3: Sa | J3: Su | K3: M | L3: Tu | M3: W | N3: Th | O3: F | P3: Sa | Q3: Su | R3: M | S3: Tu | T3: W | U3: Th | V3: F | W3: Sa | X3: Su | Y3: M | Z3: Tu | AA3: W | AB3: Th | AC3: F | AD3: Sa | AE3: Su | AF3: M | AG3: Tu | AH3: W | AI3: Th | AJ3: F | AK3: Sa | AL3: Su | AM3: M | AN3: Tu | AO3: W | AP3: Th | AQ3: F | AR3: Sa | AS3: Su | AT3: M | AU3: Tu | AV3: W | AW3: Th | AX3: F | AY3: Sa | AZ3: Su | BA3: M | BB3: Tu | BC3: W | BD3: Th | BE3: F | BF3: Sa | BG3: Su | BH3: M | BI3: Tu | BJ3: W | BK3: Th | BL3: F | BM3: Sa | BN3: Su | BO3: M | BP3: Tu | BQ3: W | BR3: Th | BS3: F | BT3: Sa | BU3: Su | BV3: M | BW3: Tu | BX3: W | BY3: Th | BZ3: F | CA3: Sa | CB3: Su | CC3: M | CD3: Tu | CE3: W | CF3: Th | CG3: F | CH3: Sa | CI3: Su | CJ3: M | CK3: Tu | CL3: W | CM3: Th | CN3: F | CO3: Sa | CP3: Su | CQ3: M | CR3: Tu | CS3: W | CT3: Th | CU3: F | CV3: Sa | CW3: Su | CX3: M | CY3: Tu | CZ3: W | DA3: Th | DB3: F | DC3: Sa | DD3: Su | DE3: M | DF3: Tu | DG3: W | DH3: Th | DI3: F | DJ3: Sa | DK3: Su | DL3: M | DM3: Tu | DN3: W | DO3: Th | DP3: F | DQ3: Sa | DR3: Su
D4: 4 | E4: 5 | F4: 6 | G4: 7 | H4: 8 | I4: 9 | J4: 10 | K4: 11 | L4: 12 | M4: 13 | N4: 14 | O4: 15 | P4: 16 | Q4: 17 | R4: 18 | S4: 19 | T4: 20 | U4: 21 | V4: 22 | W4: 23 | X4: 24 | Y4: 25 | Z4: 26 | AA4: 27 | AB4: 28 | AC4: 29 | AD4: 30 | AE4: 1 | AF4: 2 | AG4: 3 | AH4: 4 | AI4: 5 | AJ4: 6 | AK4: 7 | AL4: 8 | AM4: 9 | AN4: 10 | AO4: 11 | AP4: 12 | AQ4: 13 | AR4: 14 | AS4: 15 | AT4: 16 | AU4: 17 | AV4: 18 | AW4: 19 | AX4: 20 | AY4: 21 | AZ4: 22 | BA4: 23 | BB4: 24 | BC4: 25 | BD4: 26 | BE4: 27 | BF4: 28 | BG4: 29 | BH4: 30 | BI4: 31 | BJ4: 1 | BK4: 2 | BL4: 3 | BM4: 4 | BN4: 5 | BO4: 6 | BP4: 7 | BQ4: 8 | BR4: 9 | BS4: 10 | BT4: 11 | BU4: 12 | BV4: 13 | BW4: 14 | BX4: 15 | BY4: 16 | BZ4: 17 | CA4: 18 | CB4: 19 | CC4: 20 | CD4: 21 | CE4: 22 | CF4: 23 | CG4: 24 | CH4: 25 | CI4: 26 | CJ4: 27 | CK4: 28 | CL4: 29 | CM4: 30 | CN4: 1 | CO4: 2 | CP4: 3 | CQ4: 4 | CR4: 5 | CS4: 6 | CT4: 7 | CU4: 8 | CV4: 9 | CW4: 10 | CX4: 11 | CY4: 12 | CZ4: 13 | DA4: 14 | DB4: 15 | DC4: 16 | DD4: 17 | DE4: 18 | DF4: 19 | DG4: 20 | DH4: 21 | DI4: 22 | DJ4: 23 | DK4: 24 | DL4: 25 | DM4: 26 | DN4: 27 | DO4: 28 | DP4: 29 | DQ4: 30 | DR4: 31
B5: Contract Execution, Contract Insurances and Exchanges
B6: Design Assessment, Coordination, Shop Drawings etc_For Construction
B7: Site Inductions
A8: Mobilsation | B8: BUILDERS Proj DURATION:
B9: TEMPS
B10: Materials Store, Area establishment, signage and controls
A12: Road 5 | B12: 670LM - 2 Tees - Serving 20 Lots
A14: Road 6 | B14: 100LM - Serving 5 Lots
A16: Road 7 | B16: 500LM - Serving 19 Lots
A18: Live Connection #1
A20: Live Connection #2
A22: Contract Completion
B24: Commissioning
B25: As-Built
B26: O+M Manuals
B27: Pratical Completion
B28: Site Demobilisation
A30: Staff Count
B33: TRADESMAN_LEADING HAND | DR33: 0
B34: CREW - Fire & WAT
B35: CREW - Drainage
B36: CREW #3
B37: T/A & Apprentice
B38: TRADESMAN.1
B39: TRADESMAN.2
B41: Qty Staff On Site | D41: =D33+(D34*3)+(D35*3)+(D36*3)+D37+D38+D39 -> 0 | E41: =E33+(E34*3)+(E35*3)+(E36*3)+E37+E38+E39 -> 0 | F41: =F33+(F34*3)+(F35*3)+(F36*3)+F37+F38+F39 -> 0 | G41: =G33+(G34*3)+(G35*3)+(G36*3)+G37+G38+G39 -> 0 | H41: =H33+(H34*3)+(H35*3)+(H36*3)+H37+H38+H39 -> 0 | I41: =I33+(I34*3)+(I35*3)+(I36*3)+I37+I38+I39 -> 0 | J41: =J33+(J34*3)+(J35*3)+(J36*3)+J37+J38+J39 -> 0 | K41: =K33+(K34*3)+(K35*3)+(K36*3)+K37+K38+K39 -> 0 | ... DR41: =DR33+(DR34*3)+(DR35*3)+(DR36*3)+DR37+DR38+DR39 -> 0
B43: Total Days - LEAD HAND - PRELIM | C43: =SUM(D33:CV33) -> 0
B44: Hyd allow **
B45: Civil SW allow **
B47: Total Days - CREW - FIRE_WAT | C47: =SUM(D34:CV34) -> 0
B48: Total - CREW "Drainage" | C48: =SUM(D35:CV35) -> 0
B49: HYD - CREW "Drainage"
B50: Civil SW - CREW "Drainage"
B51: Total Days CREW 3
B52: Total Days - TA | C52: =SUM(D37:CV37) -> 0
B53: Total Days - Tradesman.1 | C53: =SUM(D38:CV38) -> 0
...

Sheet Staff Rates
B1: Project:
B2: Tricore -
B3: Stage 1 Version 1
A4: Item
B6: BASED ON:
B7: 6 - Day Week, 10Hr Day | F7: 2023 Staff Cost increase | G7: Project total cost | H7: Difference
B8: Working Days/Month | C8: 24 | F8: Current
B9: No-Work Days/Month | C9: 4 | F9: 0.025 | G9: =G8+(G8*F9) -> 0 | H9: =G9-G8 -> 0
B10: Avrg Hours / Day | C10: 8.75 | F10: 0.05 | G10: =G9+(G9*F10) -> 0 | H10: =G10-$G$8 -> 0
B11: Avrg Days / Week | C11: 6 | F11: 0.075 | G11: =G10+(G10*F11) -> 0 | H11: =G11-$G$8 -> 0
B12: Avrg Hours / Month | C12: =C10*C8 -> 210 | F12: 0.1 | G12: =G11+(G11*F12) -> 0 | H12: =G12-$G$8 -> 0
B14: STAFF | G14: Hourly Rate + 2.5% | H14: Hourly Rate + 5% | I14: Hourly Rate + 7.5% | J14: Hourly Rate + 10%
C15: Unit | D15: REQ | E15: Cost ex GST | F15: Total ex GST
B16: TRADESMAN_LEADING HAND | C16: HR | D16: 1 | E16: 94 | F16: =D16*E16 -> 94 | G16: =E16+(F16*$F$9) -> 96.35 | H16: =E16+(E16*$F$10) -> 98.7 | I16: =E16+(E16*$F$11) -> 101.05 | J16: =E16+(E16*$F$12) -> 103.4
C17: DAY | D17: 1 | E17: =E16*$C$10 -> 822.5 | F17: =D17*E17 -> 822.5 | G17: =G16*$C$10 -> 843.0625 | H17: =H16*$C$10 -> 863.625 | I17: =I16*$C$10 -> 884.1875 | J17: =J16*$C$10 -> 904.75
B18: =B16 -> TRADESMAN_LEADING HAND | C18: WEEK | D18: 1 | E18: =E17*$C$11 -> 4935 | F18: =D18*E18 -> 4935 | G18: =G17*$C$11 -> 5058.375 | H18: =H17*$C$11 -> 5181.75 | I18: =I17*$C$11 -> 5305.125 | J18: =J17*$C$11 -> 5428.5
C19: MONTH | D19: 1 | E19: =E17*$C$8 -> 19740 | F19: =D19*E19 -> 19740 | G19: =G17*$C$8 -> 20233.5 | H19: =H17*$C$8 -> 20727 | I19: =I17*$C$8 -> 21220.5 | J19: =J17*$C$8 -> 21714
B21: QTY Staff in Crew | C21: =COUNTA(B18,B19,B20) -> 1
B23: Crew #1 | C23: HR | D23: 1 | E23: =E44*2+E51 -> 254 | F23: =D23*E23 -> 254 | G23: =E23+(F23*$F$9) -> 260.35 | H23: =E23+(E23*$F$10) -> 266.7 | I23: =E23+(E23*$F$11) -> 273.05 | J23: =E23+(E23*$F$12) -> 279.4
C24: DAY | D24: 1 | E24: =E23*$C$10 -> 2222.5 | F24: =D24*E24 -> 2222.5 | G24: =G23*$C$10 -> 2278.0625 | H24: =H23*$C$10 -> 2333.625 | I24: =I23*$C$10 -> 2389.1875 | J24: =J23*$C$10 -> 2444.75
B25: =B44 -> TRADESMAN_PLUMBER_OPERATOR | C25: WEEK | D25: 1 | E25: =E24*$C$11 -> 13335 | F25: =D25*E25 -> 13335 | G25: =G24*$C$11 -> 13668.375 | H25: =H24*$C$11 -> 14001.75 | I25: =I24*$C$11 -> 14335.125 | J25: =J24*$C$11 -> 14668.5
B26: =B44 -> TRADESMAN_PLUMBER_OPERATOR | C26: MONTH | D26: 1 | E26: =E24*$C$8 -> 53340 | F26: =D26*E26 -> 53340 | G26: =G24*$C$8 -> 54673.5 | H26: =H24*$C$8 -> 56007 | I26: =I24*$C$8 -> 57340.5 | J26: =J24*$C$8 -> 58674
B27: =B51 -> T/A & Apprentice
B28: QTY Staff in Crew | C28: =COUNTA(B25,B26,B27) -> 3
B30: Crew #2 | C30: HR | D30: 1 | E30: =E44*2+E51 -> 254 | F30: =D30*E30 -> 254 | G30: =E30+(F30*$F$9) -> 260.35 | H30: =E30+(E30*$F$10) -> 266.7 | I30: =E30+(E30*$F$11) -> 273.05 | J30: =E30+(E30*$F$12) -> 279.4
C31: DAY | D31: 1 | E31: =E30*$C$10 -> 2222.5 | F31: =D31*E31 -> 2222.5 | G31: =G30*$C$10 -> 2278.0625 | H31: =H30*$C$10 -> 2333.625 | I31: =I30*$C$10 -> 2389.1875 | J31: =J30*$C$10 -> 2444.75
B32: =B44 -> TRADESMAN_PLUMBER_OPERATOR | C32: WEEK | D32: 1 | E32: =E31*$C$11 -> 13335 | F32: =D32*E32 -> 13335 | G32: =G31*$C$11 -> 13668.375 | H32: =H31*$C$11 -> 14001.75 | I32: =I31*$C$11 -> 14335.125 | J32: =J31*$C$11 -> 14668.5
B33: =B44 -> TRADESMAN_PLUMBER_OPERATOR | C33: MONTH | D33: 1 | E33: =E31*$C$8 -> 53340 | F33: =D33*E33 -> 53340 | G33: =G31*$C$8 -> 54673.5 | H33: =H31*$C$8 -> 56007 | I33: =I31*$C$8 -> 57340.5 | J33: =J31*$C$8 -> 58674
B34: =B51 -> T/A & Apprentice
B35: QTY Staff in Crew | C35: =COUNTA(B32,B33,B34) -> 3
B37: Crew #3 | C37: HR | D37: 1 | E37: =E44*2+E51 -> 254 | F37: =D37*E37 -> 254 | G37: =E37+(F37*$F$9) -> 260.35 | H37: =E37+(E37*$F$10) -> 266.7 | I37: =E37+(E37*$F$11) -> 273.05 | J37: =E37+(E37*$F$12) -> 279.4
C38: DAY | D38: 1 | E38: =E37*$C$10 -> 2222.5 | F38: =D38*E38 -> 2222.5 | G38: =G37*$C$10 -> 2278.0625 | H38: =H37*$C$10 -> 2333.625 | I38: =I37*$C$10 -> 2389.1875 | J38: =J37*$C$10 -> 2444.75
B39: =B44 -> TRADESMAN_PLUMBER_OPERATOR | C39: WEEK | D39: 1 | E39: =E38*$C$11 -> 13335 | F39: =D39*E39 -> 13335 | G39: =G38*$C$11 -> 13668.375 | H39: =H38*$C$11 -> 14001.75 | I39: =I38*$C$11 -> 14335.125 | J39: =J38*$C$11 -> 14668.5
B40: =B44 -> TRADESMAN_PLUMBER_OPERATOR | C40: MONTH | D40: 1 | E40: =E38*$C$8 -> 53340 | F40: =D40*E40 -> 53340 | G40: =G38*$C$8 -> 54673.5 | H40: =H38*$C$8 -> 56007 | I40: =I38*$C$8 -> 57340.5 | J40: =J38*$C$8 -> 58674
B41: =B51 -> T/A & Apprentice
B42: QTY Staff in Crew | C42: =COUNTA(B39,B40,B41) -> 3
B44: TRADESMAN_PLUMBER_OPERATOR | C44: HR | D44: 1 | E44: 92 | F44: =D44*E44 -> 92 | G44: =E44+(F44*$F$9) -> 94.3 | H44: =E44+(E44*$F$10) -> 96.6 | I44: =E44+(E44*$F$11) -> 98.9 | J44: =E44+(E44*$F$12) -> 101.2
C45: DAY | D45: 1 | E45: =E44*$C$10 -> 805 | F45: =D45*E45 -> 805 | G45: =G44*$C$10 -> 825.125 | H45: =H44*$C$10 -> 845.25 | I45: =I44*$C$10 -> 865.375 | J45: =J44*$C$10 -> 885.5
B46: =B44 -> TRADESMAN_PLUMBER_OPERATOR | C46: WEEK | D46: 1 | E46: =E45*$C$11 -> 4830 | F46: =D46*E46 -> 4830 | G46: =G45*$C$11 -> 4950.75 | H46: =H45*$C$11 -> 5071.5 | I46: =I45*$C$11 -> 5192.25 | J46: =J45*$C$11 -> 5313
C47: MONTH | D47: 1 | E47: =E45*$C$8 -> 19320 | F47: =D47*E47 -> 19320 | G47: =G45*$C$8 -> 19803 | H47: =H45*$C$8 -> 20286 | I47: =I45*$C$8 -> 20769 | J47: =J45*$C$8 -> 21252
...

Sheet Equip&HIRE
D2: TCS PROJECT USE | G2: CAT Rental (ROK) | J2: COATES (ROK) | M2: ONSITE
A3: DESCRIPTION | B3: QTY | D3: WEEKLY (5 day) | E3: COMMENTS | G3: WEEKLY (5 day) | H3: COMMENTS | J3: WEEKLY (5 day) | K3: COMMENTS | M3: DAILY | N3: WEEKLY (5 day) | O3: COMMENTS
A4: Skid Steer Loader_Tracked | B4: 0 | D4: 0 | G4: 0 | J4: 0 | M4: 0 | N4: 262
A5: Skid Steer Loader_Wheeled | B5: 0 | D5: 300 | E5: =B5*D5 -> 0 | G5: 250 | J5: 192 | M5: 0 | N5: 0
A7: 4.5-6Ton_Excavator | B7: 0 | D7: 200 | G7: 0 | J7: 0 | M7: 0 | N7: 0
A8: 8Ton_Excavator | B8: 0 | D8: 250 | E8: =B8*D8 -> 0 | G8: 0 | J8: 0 | M8: 0 | N8: 0
A9: 10-12Ton_Excavator | B9: 0 | D9: 310 | E9: =B9*D9 -> 0 | G9: 310 | H9: 13T | J9: 301 | K9: 12T | M9: 0 | N9: 300 | O9: 13T
A10: 14-16Ton_Excavator | B10: 0 | D10: 440 | E10: =B10*D10 -> 0 | G10: 370 | H10: 17T | J10: 375 | K10: 14T | M10: 0 | N10: 295 | O10: 14T
A11: 20-24Ton_Excavator | B11: 0 | D11: 450 | E11: =B11*D11 -> 0 | G11: 480 | H11: 25T | J11: 417 | K11: 20T | M11: 0 | N11: 444 | O11: 20T
A13: Ripper_10-12T | B13: 0 | D13: 26 | G13: 0 | J13: 25.7 | M13: 0 | N13: 0
A14: Ripper_14-16T | B14: 0 | D14: 26 | G14: 0 | J14: 25.7 | M14: 0 | N14: 21
A15: Ripper_20-24T | B15: 0 | D15: 30 | G15: 0 | J15: 30.1 | M15: 0 | N15: 23
A16: Breaker_10-12T | B16: 0 | D16: 0 | G16: 0 | J16: 0 | M16: 0 | N16: 0
A17: Auger Drive_10-12T | B17: 0 | D17: 115 | E17: =B17*D17 -> 0 | G17: 0 | J17: 0 | M17: 0 | N17: 0
A18: 300Dia Auger Drill | B18: 0 | D18: 50 | G18: 0 | J18: 0 | M18: 0 | N18: 0
A20: 2-4T_Tipper Truck | B20: 0 | D20: 180 | E20: =B20*D20 -> 0 | G20: 0 | J20: 180 | K20: 2-3T | M20: 0 | N20: 130 | O20: 2-3T
A21: 6-12T_Tipper Truck | B21: 0 | D21: 400 | E21: =B21*D21 -> 0 | G21: 0 | J21: 238 | K21: 6T | M21: 0 | N21: 0
A23: <10T_Articulated Site Tipper | B23: 0 | D23: 341 | E23: =B23*D23 -> 0 | G23: 0 | J23: 243 | K23: 9T | M23: 0 | N23: 0
A24: Upright Rammer_Wacker | B24: 0 | D24: 50 | E24: =B24*D24 -> 0 | G24: 0 | J24: 48 | M24: 0 | N24: 46
A25: Trench Roller_Dbl Drum_Remote | B25: 0 | D25: 180 | E25: =B25*D25 -> 0 | G25: 0 | J25: 121 | M25: 0 | N25: 98 | O25: Rller - padfot?
A26: <26Ft_Scissor Lift - Diesel | B26: 0 | D26: 150 | E26: =B26*D26 -> 0 | G26: 0 | J26: 89 | M26: 0 | N26: 112
A27: <26Ft_Scissor Lift - Elec | B27: 0 | D27: 0 | E27: =B27*D27 -> 0 | G27: 0 | J27: 0 | M27: 0 | N27: 0
A28: <34Ft_Boom Lift - Diesel | B28: 0 | D28: 150 | E28: =B28*D28 -> 0 | G28: 0 | J28: 96 | M28: 0 | N28: 140
A29: <34Ft_Boom Lift - Elec | B29: 0 | D29: 0 | E29: =B29*D29 -> 0 | G29: 0 | J29: 0 | M29: 0 | N29: 0
A31: Porta Loo_No Tank | B31: 0 | D31: 5 | E31: =B31*D31 -> 0 | G31: 0 | J31: 5 | M31: 0 | N31: 7.5
A32: 3.6*3m Demantable Office | B32: 0 | D32: 0 | E32: =B32*D32 -> 0 | G32: 0 | J32: 15 | K32: 42D Min. | M32: 0 | N32: 13
A33: 20Ft Shipping Container | B33: 0 | D33: 5 | E33: =B33*D33 -> 0 | G33: 0 | J33: 4 | K33: 42D Min. | M33: 0 | N33: 0
A34: Quick Cut Demo Saw | B34: 0 | D34: 0 | E34: =B34*D34 -> 0 | G34: 0 | J34: 100 | M34: 0 | N34: 50
A35: Sngl Ph_6KVA Genset | B35: 0 | D35: 50 | E35: =B35*D35 -> 0 | G35: 0 | J35: 45 | M35: 0 | N35: 35
A36: Diesel Air Compressor_Trailer | B36: 0 | D36: 0 | E36: =B36*D36 -> 0 | G36: 0 | J36: 73 | M36: 0 | N36: 68
A37: Air Breaker - Heavy | B37: 0 | D37: 0 | E37: =B37*D37 -> 0 | G37: 0 | J37: 34 | M37: 0 | N37: 0
A38: Air Hose <10m | B38: 0 | D38: 0 | E38: =B38*D38 -> 0 | G38: 0 | J38: 9 | M38: 0 | N38: 1.2
A39: Elec Breaker/Jachammer | B39: 0 | D39: 0 | E39: =B39*D39 -> 0 | G39: 0 | J39: 45 | M39: 0 | N39: 0
A40: Flexdrive Motor Unit | B40: 0 | D40: 0 | E40: =B40*D40 -> 0 | G40: 0 | J40: 25 | M40: 0 | N40: 27
A41: Flexdrive_Pump Shaft | B41: 0 | D41: 0 | E41: =B41*D41 -> 0 | G41: 0 | J41: 30 | M41: 0 | N41: 22
A42: Temporary Power Board | B42: 0 | D42: 25 | E42: =B42*D42 -> 0 | G42: 0 | J42: 30 | M42: 0 | N42: 17
A44: Dual CabUte | B44: 0 | D44: 125 | E44: =B44*D44 -> 0 | G44: 0 | J44: 0 | M44: 0 | N44: 0
A45: 10m3_Skip Bin | B45: 0 | D45: 40 | E45: =B45*D45 -> 0 | G45: 0 | J45: 0 | M45: 0 | N45: 0
A46: Vac Truck / HR | B46: 0 | D46: 200 | E46: =B46*D46 -> 0 | G46: 0 | J46: 0 | M46: 0 | N46: 0
B47: 0 | D47: 0 | G47: 0 | J47: 0 | M47: 0 | N47: 0
...

Sheet Civil Rate  BOQ 
A6: Adress | I6: Contract
A7: ROADWORKS AND CIVIL SERVICES
A9: BILL OF QUANTITIES | I9: Date
C11: SUMMARY
A14: 1 | C14: TOTAL PART A - PRELIMS, SITE ESTABLISHMENT, E&S Controls & PREPARATIONS | L14: =O79 -> 0
A15: 2 | C15: TOTAL PART B - EARTHWORKS | L15: =O218 -> 0
A16: 3 | C16: TOTAL PART C - ROADWORKS | L16: =O322 -> 0
A17: 4 | C17: TOTAL PART D - STORMWATER DRAINAGE | L17: =O463 -> 25129.865
A18: 5 | C18: TOTAL PART E - POTABLE WATER RETICULATION | L18: =O550 -> 0
A19: 6 | C19: TOTAL PART F - SEWERAGE RETICULATION (RIGS) | L19: =O679 -> 0
A20: 7 | C20: TOTAL PART G - STORMWATER TREATMENT | L20: =O829 -> 0
A21: 8 | C21: TOTAL PART H - ELECTRICAL & COMMUNICATIONS | L21: =O869 -> 0
A22: 9 | C22: TOTAL PART I - INTERNAL PLUMBING | L22: =O950 -> 0
A24: 9 | C24: SUB-TOTAL: | L24: =SUM(L14:M23) -> 25129.865
A25: 14 | C25: COMBINED QLEAVE LEVY AND WORKPLACE HEALTH AND SAFETY FEE | L25: (By Principal) | Q25: =L24/6 -> 4188.3109
A27: ITEM DESCRIPTION | H27: QTY UNIT | L27: Rate | O27: Amount
A30: PART A - SITE ESTABLISHMENT AND PREPARATION
A32: 1. Site establishment including mobilisation of plant and personnel. | J32: Item | L32: 6081.91 | O32: =H32*L32 -> 0
A33: 1. Site DeMob & Clean | J33: Item | L33: 3100 | O33: =H33*L33 -> 0
A35: 2. Supply and erect approved 1200mm x 900mm project Notice | J35: Item | L35: 364.91 | O35: =H35*L35 -> 0
A36: board to Local Authority requirements.
A38: 3. Provision for traffic, including installation of temporary warning | J38: Item | L38: 1450 | O38: =H38*L38 -> 0
A39: devices and/or traffic controllers and /or traffic controllers and
A40: maintenance of access for site traffic, in accordance with approved
A41: Traffic Management Plan (to be organised by contractor)
A43: 4. Allowance for service location and potholing as required to | J43: Item | L43: 1715.1 | O43: =H43*L43 -> 0
A44: confirm existing services and protect infrastructure throughout
A45: construction.
A47: 5. Supply all materials, construct, maintain and remove on | J47: Item | L47: 5850 | O47: =H47*L47 -> 0
A48: completion of works the erosion and sediment control measures as
A49: detailed. Note that the Contractor must engage their own CPESC for
A50: ongoing management of ESC Control measures on site.
A52: 6.Clearing and grubbing, including removal of trees and grasses, | J52: Item | L52: 650 | O52: =H52*L52 -> 0
A53: existing fences, rubbish and debris from all work areas, including
A54: mulching of trees & vegetation or removal from site as directed.
A56: 7. Provision of Level 4 Arborist for attendance at pre-start meeting | J56: Item | L56: 6252.2
A57: and during cleaning operations.
A59: 8. Implementation of approved Vegetation Management Plan | J59: Item | L59: 4378.97 | O59: =H59*L59 -> 0
A60: procedures, including supply and establishent of temporary fencing
A61: for protection of identified trees, vegetation to be preserved &
...
